Workbook

Sheet README
A1: Commonwealth Bank Social Media Dataset
A2: Purpose
A3: This simulated dataset supports Task 3 of the Commonwealth Bank data science program. It mirrors the type of social media content and engagement information learners could analyze without requiring access to a live X/Twitter account.
A4: Important note
A5: All posts and metrics in this workbook are fictional and created for educational use. They should not be treated as real Commonwealth Bank posts, real customer comments, or real performance data.
A6: How learners can use it
A7: Use the Social_Media_Posts sheet to explore sentiment, engagement, customer pain points, recurring topics, and trends over time. The Data_Dictionary sheet explains each column and how it connects to social media/API concepts.
A8: Suggested analyses
A9: 1. Identify the topics that appear most often. 2. Compare engagement across topics, formats, and post types. 3. Review positive, negative, neutral, and mixed sentiment. 4. Find posts with high views but low engagement. 5. Summarize customer questions, complaints, praise, and feature feedback.

Sheet Social_Media_Posts
A1: post_id | B1: post_datetime | C1: post_type | D1: author_type | E1: author_follower_bucket | F1: post_text | G1: topic | H1: content_format | I1: hashtags | J1: mentions_commbank | K1: sentiment_label | L1: sentiment_score | M1: likes | N1: replies | O1: reposts | P1: quote_posts | Q1: views | R1: link_clicks | S1: total_engagements | T1: engagement_rate | U1: day_of_week | V1: customer_intent | W1: response_needed | X1: api_field_examples
A2: SM048 | B2: 46166.682 | C2: Original post | D2: CommBank | E2: 50k+ | F2: Reminder: genuine bank staff will not ask you to transfer money to a 'safe account'. Stop, check and report suspicious requests. | G2: Fraud & scams | H2: Text + image | I2: #ScamAwareness #StopCheckReport | J2: No | K2: Neutral | L2: 0.16 | M2: 1280 | N2: 118 | O2: 520 | P2: 47 | Q2: 210000 | R2: 10200 | S2: =SUM(M2:P2)+R2 -> 12165 | T2: =IFERROR(S2/Q2,0) -> 0.057928571 | U2: =TEXT(B2,"dddd") -> Sunday | V2: Educational content | W2: No | X2: text, entities.hashtags, public_metrics
A3: SM031 | B3: 46147.458 | C3: Original post | D3: CommBank | E3: 50k+ | F3: Today we are sharing practical tips for protecting older family members from impersonation scams. | G3: Fraud & scams | H3: Link | I3: #ScamAwareness #FamilySafety | J3: No | K3: Positive | L3: 0.42 | M3: 900 | N3: 82 | O3: 360 | P3: 33 | Q3: 170000 | R3: 8900 | S3: =SUM(M3:P3)+R3 -> 10275 | T3: =IFERROR(S3/Q3,0) -> 0.060441176 | U3: =TEXT(B3,"dddd") -> Tuesday | V3: Educational content | W3: No | X3: text, entities.urls, public_metrics
A4: SM013 | B4: 46134.417 | C4: Original post | D4: CommBank | E4: 50k+ | F4: Three signs a message may be a scam: urgency, unusual links and requests for codes. Pause before you respond. | G4: Security education | H4: Text + video | I4: #CyberSafety #ScamAwareness | J4: No | K4: Positive | L4: 0.46 | M4: 1100 | N4: 72 | O4: 405 | P4: 31 | Q4: 156000 | R4: 7400 | S4: =SUM(M4:P4)+R4 -> 9008 | T4: =IFERROR(S4/Q4,0) -> 0.05774359 | U4: =TEXT(B4,"dddd") -> Wednesday | V4: Educational content | W4: No | X4: text, attachments.media_keys, entities.hashtags
A5: SM057 | B5: 46182.392 | C5: Original post | D5: CommBank | E5: 50k+ | F5: If a payment request arrives unexpectedly, call the person on a trusted number before sending money. | G5: Security education | H5: Text + image | I5: #CyberSafety #StopCheckReport | J5: No | K5: Neutral | L5: 0.19 | M5: 740 | N5: 63 | O5: 295 | P5: 22 | Q5: 151000 | R5: 7200 | S5: =SUM(M5:P5)+R5 -> 8320 | T5: =IFERROR(S5/Q5,0) -> 0.055099338 | U5: =TEXT(B5,"dddd") -> Tuesday | V5: Educational content | W5: No | X5: text, entities.hashtags, public_metrics
A6: SM050 | B6: 46169.403 | C6: Original post | D6: CommBank | E6: 50k+ | F6: We are updating the app home screen to make upcoming bills and scheduled payments easier to find. | G6: Digital banking | H6: Text + image | I6: #CommBankApp | J6: No | K6: Positive | L6: 0.44 | M6: 720 | N6: 156 | O6: 132 | P6: 35 | Q6: 149000 | R6: 4800 | S6: =SUM(M6:P6)+R6 -> 5843 | T6: =IFERROR(S6/Q6,0) -> 0.039214765 | U6: =TEXT(B6,"dddd") -> Wednesday | V6: Product update | W6: No | X6: text, public_metrics, attachments.media_keys
A7: SM022 | B7: 46140.51 | C7: Original post | D7: CommBank | E7: 50k+ | F7: We have added clearer transaction labels in the app to help you recognise subscriptions and recurring payments. | G7: Digital banking | H7: Text + image | I7: #CommBankApp | J7: No | K7: Positive | L7: 0.55 | M7: 980 | N7: 104 | O7: 218 | P7: 26 | Q7: 142500 | R7: 6100 | S7: =SUM(M7:P7)+R7 -> 7428 | T7: =IFERROR(S7/Q7,0) -> 0.052126316 | U7: =TEXT(B7,"dddd") -> Tuesday | V7: Product update | W7: No | X7: text, public_metrics, attachments.media_keys
A8: SM028 | B8: 46145.556 | C8: Original post | D8: CommBank | E8: 50k+ | F8: If you are buying online, use secure payment options and be cautious of sellers asking to move the conversation off-platform. | G8: Fraud & scams | H8: Text + video | I8: #OnlineSafety #ScamAwareness | J8: No | K8: Neutral | L8: 0.2 | M8: 520 | N8: 44 | O8: 205 | P8: 15 | Q8: 132000 | R8: 6900 | S8: =SUM(M8:P8)+R8 -> 7684 | T8: =IFERROR(S8/Q8,0) -> 0.058212121 | U8: =TEXT(B8,"dddd") -> Sunday | V8: Educational content | W8: No | X8: text, attachments.media_keys, entities.hashtags
A9: SM055 | B9: 46178.5 | C9: Original post | D9: CommBank | E9: 50k+ | F9: We are celebrating teams volunteering with local partners to improve financial confidence in regional communities. | G9: Community | H9: Text + video | I9: #Community #Volunteering | J9: No | K9: Positive | L9: 0.69 | M9: 860 | N9: 44 | O9: 188 | P9: 14 | Q9: 125000 | R9: 3100 | S9: =SUM(M9:P9)+R9 -> 4206 | T9: =IFERROR(S9/Q9,0) -> 0.033648 | U9: =TEXT(B9,"dddd") -> Friday | V9: Campaign | W9: No | X9: text, attachments.media_keys, entities.hashtags
A10: SM033 | B10: 46148.691 | C10: Original post | D10: CommBank | E10: 50k+ | F10: We are trialling new in-app prompts that ask customers to pause before sending money to a first-time payee. | G10: Security education | H10: Text + image | I10: #CyberSafety | J10: No | K10: Positive | L10: 0.4 | M10: 480 | N10: 93 | O10: 156 | P10: 24 | Q10: 124000 | R10: 4100 | S10: =SUM(M10:P10)+R10 -> 4853 | T10: =IFERROR(S10/Q10,0) -> 0.039137097 | U10: =TEXT(B10,"dddd") -> Wednesday | V10: Product update | W10: No | X10: text, public_metrics, attachments.media_keys
A11: SM059 | B11: 46185.465 | C11: Original post | D11: CommBank | E11: 50k+ | F11: Our app update includes accessibility improvements for screen readers and clearer error messages. | G11: Digital banking | H11: Text + image | I11: #CommBankApp #Accessibility | J11: No | K11: Positive | L11: 0.61 | M11: 690 | N11: 73 | O11: 148 | P11: 20 | Q11: 121000 | R11: 3900 | S11: =SUM(M11:P11)+R11 -> 4831 | T11: =IFERROR(S11/Q11,0) -> 0.03992562 | U11: =TEXT(B11,"dddd") -> Friday | V11: Product update | W11: No | X11: text, entities.hashtags, public_metrics
A12: SM001 | B12: 46127.378 | C12: Original post | D12: CommBank | E12: 50k+ | F12: Scam alert: We will never ask for your NetBank password or one-time code by text message. If a message feels suspicious, stop and check before clicking. | G12: Fraud & scams | H12: Text + image | I12: #ScamAwareness #CyberSafety | J12: No | K12: Neutral | L12: 0.1 | M12: 842 | N12: 96 | O12: 310 | P12: 28 | Q12: 118000 | R12: 4200 | S12: =SUM(M12:P12)+R12 -> 5476 | T12: =IFERROR(S12/Q12,0) -> 0.04640678 | U12: =TEXT(B12,"dddd") -> Wednesday | V12: Educational content | W12: No | X12: text, created_at, public_metrics, entities.hashtags
A13: SM039 | B13: 46154.385 | C13: Original post | D13: CommBank | E13: 50k+ | F13: Card controls can help if your card is misplaced. Temporarily lock, unlock or replace your card in the app. | G13: Card services | H13: Text + video | I13: #CommBankApp | J13: No | K13: Positive | L13: 0.38 | M13: 670 | N13: 58 | O13: 142 | P13: 16 | Q13: 111000 | R13: 5300 | S13: =SUM(M13:P13)+R13 -> 6186 | T13: =IFERROR(S13/Q13,0) -> 0.05572973 | U13: =TEXT(B13,"dddd") -> Tuesday | V13: Educational content | W13: No | X13: text, attachments.media_keys, public_metrics
... A19: SM037 | B19: 46151.434 | C19: Original post | D19: CommBank | E19: 50k+ | F19: Know the difference between available balance and current balance before making a large purchase. | G19: Financial wellbeing | H19: Text + image | I19: #MoneyTips #BankingBasics | J19: No | K19: Neutral | L19: 0.25 | M19: 390 | N19: 29 | O19: 85 | P19: 4 | Q19: 90300 | R19: 2500 | S19: =SUM(M19:P19)+R19 -> 3008 | T19: =IFERROR(S19/Q19,0) -> 0.033311185 | U19: =TEXT(B19,"dddd") -> Saturday | V19: Educational content | W19: No | X19: text, entities.hashtags, public_metrics
A20: SM044 | B20: 46160.372 | C20: Original post | D20: CommBank | E20: 50k+ | F20: Before tax time, check that your bank statements and interest summaries are easy to access in NetBank. | G20: Digital banking | H20: Link | I20: #TaxTime #NetBank | J20: No | K20: Neutral | L20: 0.18 | M20: 240 | N20: 26 | O20: 58 | P20: 6 | Q20: 88000 | R20: 2100 | S20: =SUM(M20:P20)+R20 -> 2430 | T20: =IFERROR(S20/Q20,0) -> 0.027613636 | U20: =TEXT(B20,"dddd") -> Monday | V20: Educational content | W20: No | X20: text, entities.urls, public_metrics | AA20: =COUNTA(Social_Media_Posts!K:K)-1 -> 60
A21: SM004 | B21: 46128.521 | C21: Original post | D21: CommBank | E21: 50k+ | F21: New budget habit: split your weekly spend into essentials, savings and fun money before the weekend starts. | G21: Financial wellbeing | H21: Text + image | I21: #MoneyTips #Budgeting | J21: No | K21: Positive | L21: 0.58 | M21: 620 | N21: 42 | O21: 128 | P21: 12 | Q21: 84200 | R21: 5100 | S21: =SUM(M21:P21)+R21 -> 5902 | T21: =IFERROR(S21/Q21,0) -> 0.070095012 | U21: =TEXT(B21,"dddd") -> Thursday | V21: Educational content | W21: No | X21: text, created_at, public_metrics, media_keys
A22: SM046 | B22: 46163.542 | C22: Original post | D22: CommBank | E22: 50k+ | F22: Thinking about your first credit card? Compare fees, interest rates and repayment habits before applying. | G22: Financial wellbeing | H22: Link | I22: #BankingBasics #MoneyTips | J22: No | K22: Neutral | L22: 0.2 | M22: 280 | N22: 37 | O22: 69 | P22: 9 | Q22: 79000 | R22: 3400 | S22: =SUM(M22:P22)+R22 -> 3795 | T22: =IFERROR(S22/Q22,0) -> 0.048037975 | U22: =TEXT(B22,"dddd") -> Thursday | V22: Educational content | W22: No | X22: text, entities.urls, public_metrics
A23: SM018 | B23: 46137.674 | C23: Original post | D23: CommBank | E23: 50k+ | F23: Travel tip: tell us before you go overseas and check card controls in the app before your first purchase. | G23: Card services | H23: Link | I23: #TravelMoney | J23: No | K23: Neutral | L23: 0.24 | M23: 260 | N23: 34 | O23: 49 | P23: 7 | Q23: 74400 | R23: 1650 | S23: =SUM(M23:P23)+R23 -> 2000 | T23: =IFERROR(S23/Q23,0) -> 0.02688172 | U23: =TEXT(B23,"dddd") -> Saturday | V23: Educational content | W23: No | X23: text, entities.urls, public_metrics
A24: SM008 | B24: 46130.74 | C24: Original post | D24: CommBank | E24: 50k+ | F24: Planning a home renovation? Compare quotes, keep a buffer for surprises and avoid transferring deposits until you verify the business. | G24: Financial wellbeing | H24: Link | I24: #HomeBudget #MoneySafety | J24: No | K24: Neutral | L24: 0.22 | M24: 208 | N24: 19 | O24: 42 | P24: 5 | Q24: 61200 | R24: 390 | S24: =SUM(M24:P24)+R24 -> 664 | T24: =IFERROR(S24/Q24,0) -> 0.010849673 | U24: =TEXT(B24,"dddd") -> Saturday | V24: Educational content | W24: No | X24: text, entities.urls, public_metrics
A25: SM020 | B25: 46138.375 | C25: Original post | D25: CommBank | E25: 50k+ | F25: Small business owners: join our free webinar on cash flow planning and preparing for quieter trading periods. | G25: Business banking | H25: Link | I25: #SmallBusiness #CashFlow | J25: No | K25: Positive | L25: 0.48 | M25: 188 | N25: 17 | O25: 66 | P25: 3 | Q25: 54300 | R25: 2300 | S25: =SUM(M25:P25)+R25 -> 2574 | T25: =IFERROR(S25/Q25,0) -> 0.047403315 | U25: =TEXT(B25,"dddd") -> Sunday | V25: Campaign | W25: No | X25: text, entities.urls, public_metrics
A26: SM032 | B26: 46147.501 | C26: Quote post | D26: News/media | E26: 50k+ | F26: Useful consumer safety advice from @CommBank as impersonation scams continue to target older Australians. | G26: Fraud & scams | H26: Text | I26: #ScamAwareness | J26: Yes | K26: Positive | L26: 0.45 | M26: 230 | N26: 18 | O26: 71 | P26: 9 | Q26: 31000 | R26: 0 | S26: =SUM(M26:P26)+R26 -> 328 | T26: =IFERROR(S26/Q26,0) -> 0.010580645 | U26: =TEXT(B26,"dddd") -> Tuesday | V26: News/update | W26: No | X26: text, referenced_tweets, public_metrics
A27: SM036 | B27: 46149.335 | C27: Reply | D27: CommBank | E27: 50k+ | F27: We are aware some customers are seeing delays with PayID transfers and our teams are investigating. We will share updates as soon as possible. | G27: Outage/service issue | H27: Text | I27: #ServiceUpdate | J27: Yes | K27: Neutral | L27: 0 | M27: 141 | N27: 47 | O27: 39 | P27: 12 | Q27: 21900 | R27: 0 | S27: =SUM(M27:P27)+R27 -> 239 | T27: =IFERROR(S27/Q27,0) -> 0.010913242 | U27: =TEXT(B27,"dddd") -> Thursday | V27: Customer support | W27: No | X27: text, conversation_id, public_metrics
A28: SM027 | B28: 46144.425 | C28: Mention | D28: Customer | E28: 501-5k | F28: The new transaction labels are helpful, but my rent payment is now showing as entertainment, which is... optimistic. | G28: Digital banking | H28: Text | J28: Yes | K28: Mixed | L28: -0.05 | M28: 105 | N28: 11 | O28: 14 | P28: 2 | Q28: 9800 | R28: 0 | S28: =SUM(M28:P28)+R28 -> 132 | T28: =IFERROR(S28/Q28,0) -> 0.013469388 | U28: =TEXT(B28,"dddd") -> Saturday | V28: Feature feedback | W28: No | X28: text, entities.mentions
A29: SM035 | B29: 46149.312 | C29: Mention | D29: Customer | E29: 0-500 | F29: Is PayID down? Two people have tried to pay me and both transfers are stuck. | G29: Outage/service issue | H29: Text | I29: #PayID | J29: Yes | K29: Negative | L29: -0.74 | M29: 52 | N29: 21 | O29: 8 | P29: 3 | Q29: 7700 | R29: 0 | S29: =SUM(M29:P29)+R29 -> 84 | T29: =IFERROR(S29/Q29,0) -> 0.010909091 | U29: =TEXT(B29,"dddd") -> Thursday | V29: Question | W29: Yes | X29: text, entities.hashtags, entities.mentions
A30: SM052 | B30: 46170.552 | C30: Mention | D30: Customer | E30: 501-5k | F30: Credit where due: the fraud team called quickly after I reported a suspicious transfer. | G30: Fraud & scams | H30: Text | J30: Yes | K30: Positive | L30: 0.76 | M30: 112 | N30: 6 | O30: 18 | P30: 1 | Q30: 7600 | R30: 0 | S30: =SUM(M30:P30)+R30 -> 137 | T30: =IFERROR(S30/Q30,0) -> 0.018026316 | U30: =TEXT(B30,"dddd") -> Thursday | V30: Praise | W30: No | X30: text, entities.mentions, public_metrics
A31: SM056 | B31: 46179.649 | C31: Quote post | D31: Community org | E31: 501-5k | F31: Thank you @CommBank for supporting practical financial education in our region. | G31: Community | H31: Text + image | I31: #Community | J31: Yes | K31: Positive | L31: 0.88 | M31: 122 | N31: 4 | O31: 28 | P31: 2 | Q31: 6900 | R31: 0 | S31: =SUM(M31:P31)+R31 -> 156 | T31: =IFERROR(S31/Q31,0) -> 0.022608696 | U31: =TEXT(B31,"dddd") -> Saturday | V31: Praise | W31: No | X31: text, referenced_tweets, entities.mentions
A32: SM014 | B32: 46134.433 | C32: Quote post | D32: Scam awareness org | E32: 5k-50k | F32: Good practical reminder from @CommBank. The 'urgent action required' wording is still one of the biggest red flags. | G32: Security education | H32: Text | I32: #ScamAwareness | J32: Yes | K32: Positive | L32: 0.67 | M32: 96 | N32: 6 | O32: 31 | P32: 4 | Q32: 6700 | R32: 0 | S32: =SUM(M32:P32)+R32 -> 137 | T32: =IFERROR(S32/Q32,0) -> 0.020447761 | U32: =TEXT(B32,"dddd") -> Wednesday | V32: Educational content | W32: No | X32: text, referenced_tweets, entities.mentions
A33: SM040 | B33: 46154.41 | C33: Reply | D33: Customer | E33: 501-5k | F33: This saved me last month. Found the card under my car seat after locking it in the app. | G33: Card services | H33: Text | J33: Yes | K33: Positive | L33: 0.83 | M33: 89 | N33: 5 | O33: 9 | P33: 0 | Q33: 6000 | R33: 0 | S33: =SUM(M33:P33)+R33 -> 103 | T33: =IFERROR(S33/Q33,0) -> 0.017166667 | U33: =TEXT(B33,"dddd") -> Tuesday | V33: Praise | W33: No | X33: text, referenced_tweets
A34: SM054 | B34: 46175.764 | C34: Mention | D34: Customer | E34: 0-500 | F34: Can the app notify me before a direct debit if my balance is low? That would prevent a lot of stress. | G34: Digital banking | H34: Text | J34: Yes | K34: Mixed | L34: 0.15 | M34: 84 | N34: 10 | O34: 11 | P34: 1 | Q34: 5900 | R34: 0 | S34: =SUM(M34:P34)+R34 -> 106 | T34: =IFERROR(S34/Q34,0) -> 0.017966102 | U34: =TEXT(B34,"dddd") -> Tuesday | V34: Feature feedback | W34: No | X34: text, entities.mentions
A35: SM049 | B35: 46166.712 | C35: Mention | D35: Customer | E35: 0-500 | F35: A caller used the safe account line on my mum today. She hung up because she'd seen your post. | G35: Fraud & scams | H35: Text | J35: Yes | K35: Positive | L35: 0.66 | M35: 76 | N35: 4 | O35: 13 | P35: 0 | Q35: 5200 | R35: 0 | S35: =SUM(M35:P35)+R35 -> 93 | T35: =IFERROR(S35/Q35,0) -> 0.017884615 | U35: =TEXT(B35,"dddd") -> Sunday | V35: Praise | W35: No | X35: text, entities.mentions
A36: SM012 | B36: 46133.753 | C36: Mention | D36: Customer | E36: 0-500 | F36: My transfer has been pending for hours and I can't find a clear status page. Is there an outage? | G36: Outage/service issue | H36: Text | J36: Yes | K36: Negative | L36: -0.76 | M36: 33 | N36: 22 | O36: 4 | P36: 2 | Q36: 5200 | R36: 0 | S36: =SUM(M36:P36)+R36 -> 61 | T36: =IFERROR(S36/Q36,0) -> 0.011730769 | U36: =TEXT(B36,"dddd") -> Tuesday | V36: Question | W36: Yes | X36: text, entities.mentions, created_at
A37: SM045 | B37: 46161.799 | C37: Mention | D37: Customer | E37: 0-500 | F37: Trying to download statements and the page keeps refreshing. Anyone else? | G37: Digital banking | H37: Text | I37: #NetBank | J37: Yes | K37: Negative | L37: -0.57 | M37: 36 | N37: 13 | O37: 5 | P37: 1 | Q37: 4600 | R37: 0 | S37: =SUM(M37:P37)+R37 -> 55 | T37: =IFERROR(S37/Q37,0) -> 0.011956522 | U37: =TEXT(B37,"dddd") -> Tuesday | V37: Question | W37: Yes | X37: text, entities.hashtags, entities.mentions
A38: SM006 | B38: 46129.368 | C38: Mention | D38: Customer | E38: 0-500 | F38: @CommBank app keeps timing out this morning. I need to pay rent before work. | G38: Digital banking | H38: Text | J38: Yes | K38: Negative | L38: -0.82 | M38: 41 | N38: 18 | O38: 7 | P38: 1 | Q38: 4500 | R38: 0 | S38: =SUM(M38:P38)+R38 -> 67 | T38: =IFERROR(S38/Q38,0) -> 0.014888889 | U38: =TEXT(B38,"dddd") -> Friday | V38: Complaint | W38: Yes | X38: text, entities.mentions, created_at
A39: SM030 | B39: 46146.365 | C39: Mention | D39: Customer | E39: 0-500 | F39: Locked out of NetBank after changing phones. The recovery steps are not clear. | G39: Digital banking | H39: Text | J39: Yes | K39: Negative | L39: -0.69 | M39: 39 | N39: 15 | O39: 4 | P39: 1 | Q39: 4300 | R39: 0 | S39: =SUM(M39:P39)+R39 -> 59 | T39: =IFERROR(S39/Q39,0) -> 0.01372093 | U39: =TEXT(B39,"dddd") -> Monday | V39: Complaint | W39: Yes | X39: text, entities.mentions
A40: SM016 | B40: 46135.63 | C40: Reply | D40: Community org | E40: 501-5k | F40: Proud to be part of this program. The digital skills sessions have already helped our clients feel safer online. | G40: Community | H40: Text | J40: Yes | K40: Positive | L40: 0.86 | M40: 64 | N40: 3 | O40: 13 | P40: 1 | Q40: 4200 | R40: 0 | S40: =SUM(M40:P40)+R40 -> 81 | T40: =IFERROR(S40/Q40,0) -> 0.019285714 | U40: =TEXT(B40,"dddd") -> Thursday | V40: Praise | W40: No | X40: text, author_id, public_metrics
A41: SM058 | B41: 46183.842 | C41: Mention | D41: Customer | E41: 0-500 | F41: Why is there no clear scam reporting button in the app? I had to search around for it. | G41: Fraud & scams | H41: Text | J41: Yes | K41: Negative | L41: -0.64 | M41: 45 | N41: 12 | O41: 4 | P41: 1 | Q41: 4100 | R41: 0 | S41: =SUM(M41:P41)+R41 -> 62 | T41: =IFERROR(S41/Q41,0) -> 0.015121951 | U41: =TEXT(B41,"dddd") -> Wednesday | V41: Complaint | W41: Yes | X41: text, entities.mentions
A42: SM051 | B42: 46169.42 | C42: Reply | D42: Customer | E42: 0-500 | F42: Please do not move everything again. The last redesign made regular transfers harder to find. | G42: Digital banking | H42: Text | J42: Yes | K42: Negative | L42: -0.49 | M42: 67 | N42: 12 | O42: 5 | P42: 2 | Q42: 3900 | R42: 0 | S42: =SUM(M42:P42)+R42 -> 86 | T42: =IFERROR(S42/Q42,0) -> 0.022051282 | U42: =TEXT(B42,"dddd") -> Wednesday | V42: Feature feedback | W42: No | X42: text, referenced_tweets
A43: SM009 | B43: 46131.472 | C43: Mention | D43: Business customer | E43: 501-5k | F43: Our small business card payment issue was sorted quickly today. Appreciate the support team calling back. | G43: Business banking | H43: Text | J43: Yes | K43: Positive | L43: 0.74 | M43: 53 | N43: 4 | O43: 8 | P43: 1 | Q43: 3900 | R43: 0 | S43: =SUM(M43:P43)+R43 -> 66 | T43: =IFERROR(S43/Q43,0) -> 0.016923077 | U43: =TEXT(B43,"dddd") -> Sunday | V43: Praise | W43: No | X43: text, author_id, public_metrics
A44: SM042 | B44: 46156.626 | C44: Reply | D44: Customer | E44: 0-500 | F44: Good, but customers also want greener lending options and clearer reporting. | G44: Sustainability | H44: Text | J44: Yes | K44: Mixed | L44: 0.02 | M44: 58 | N44: 8 | O44: 6 | P44: 1 | Q44: 3400 | R44: 0 | S44: =SUM(M44:P44)+R44 -> 73 | T44: =IFERROR(S44/Q44,0) -> 0.021470588 | U44: =TEXT(B44,"dddd") -> Thursday | V44: Feature feedback | W44: No | X44: text, referenced_tweets
A45: SM017 | B45: 46136.347 | C45: Mention | D45: Customer | E45: 0-500 | F45: Branch wait times are rough lately. I just need a replacement card and couldn't get through on chat. | G45: Branch/ATM | H45: Text | J45: Yes | K45: Negative | L45: -0.7 | M45: 28 | N45: 12 | O45: 3 | P45: 1 | Q45: 3100 | R45: 0 | S45: =SUM(M45:P45)+R45 -> 44 | T45: =IFERROR(S45/Q45,0) -> 0.014193548 | U45: =TEXT(B45,"dddd") -> Friday | V45: Complaint | W45: Yes | X45: text, entities.mentions
...

Sheet Data_Dictionary
A1: Column | B1: Description | C1: Student use | D1: X/Twitter API or analytics concept
A2: post_id | B2: Unique identifier for each simulated social media item. | C2: Reference individual posts when discussing findings. | D2: id
A3: post_datetime | B3: Date and time the post was published. | C3: Analyze timing, trends, and day-of-week patterns. | D3: created_at
A4: post_type | B4: Whether the row is a brand post, customer reply, mention, or quote post. | C4: Compare original posts with customer interactions. | D4: referenced_tweets, conversation_id
A5: author_type | B5: Simplified category of the account that created the post. | C5: Explore who is engaging with the brand. | D5: author_id with user profile enrichment
A6: author_follower_bucket | B6: Approximate audience-size bucket for the author. | C6: Compare engagement from smaller vs. larger accounts. | D6: public_metrics.followers_count
A7: post_text | B7: Simulated text content of the social media post. | C7: Perform topic, keyword, and sentiment analysis. | D7: text
A8: topic | B8: Curated topic label for the post. | C8: Group posts into themes such as fraud, app issues, or financial wellbeing. | D8: Derived classification from text/entities
A9: content_format | B9: Simplified format of the post: text, image, video, link, etc. | C9: Compare engagement by format. | D9: attachments, media_keys, entities.urls
A10: hashtags | B10: Hashtags included in the simulated post. | C10: Identify recurring campaign or topic markers. | D10: entities.hashtags
A11: mentions_commbank | B11: Whether the post mentions Commonwealth Bank. | C11: Separate brand-originated posts from customer mentions. | D11: entities.mentions
A12: sentiment_label | B12: Curated sentiment category. | C12: Summarize positive, negative, neutral, and mixed responses. | D12: Derived NLP output
... A25: api_field_examples | B25: Examples of API fields or concepts that could produce similar information. | C25: Connect the dataset back to API documentation. | D25: Documentation mapping

Sheet Analysis_Prompts
A1: Analysis area | B1: Question learners can answer with the dataset | C1: Relevant columns
A2: Topic analysis | B2: Which topics appear most often, and what do those topics suggest customers care about? | C2: topic, post_text, hashtags
A3: Engagement analysis | B3: Which posts generate the most total engagement? Do the highest-view posts also receive the highest engagement? | C3: likes, replies, reposts, quote_posts, views, link_clicks, total_engagements, engagement_rate
A4: Sentiment analysis | B4: Which topics have the most positive, negative, neutral, or mixed sentiment? | C4: topic, sentiment_label, sentiment_score
A5: Customer support | B5: Which posts likely require a response from CommBank, and what themes do they share? | C5: post_type, customer_intent, response_needed, topic, post_text
A6: Trend analysis | B6: Do certain topics or sentiment patterns appear more often on specific dates or days of the week? | C6: post_datetime, day_of_week, topic, sentiment_label
A7: Marketing insight | B7: Which formats or campaign themes appear to resonate most with audiences? | C7: content_format, hashtags, topic, engagement_rate
A8: Product insight | B8: What app, NetBank, card, or service improvements are customers requesting? | C8: topic, customer_intent, post_text
A9: Risk insight | B9: What scam or security concerns are most visible in the data? | C9: topic, customer_intent, sentiment_label, post_text

Sheet Analysis
A1: Q1 Topic analysis | B1: Which topics appear most often, and what do those topics suggest customers care about?
A2: Topic | B2: Number of Posts
A3: Fraud & scams | B3: =COUNTIF(Social_Media_Posts!G:G,A3) -> 11
A4: Financial wellbeing | B4: =COUNTIF(Social_Media_Posts!G:G,A4) -> 9
A5: Digital banking | B5: =COUNTIF(Social_Media_Posts!G:G,A5) -> 13
A6: Customer support | B6: =COUNTIF(Social_Media_Posts!G:G,A6) -> 1
A7: Business banking | B7: =COUNTIF(Social_Media_Posts!G:G,A7) -> 3
A8: Outage/service issue | B8: =COUNTIF(Social_Media_Posts!G:G,A8) -> 5
A9: Security education | B9: =COUNTIF(Social_Media_Posts!G:G,A9) -> 5
A10: Community | B10: =COUNTIF(Social_Media_Posts!G:G,A10) -> 4
A11: Branch/ATM | B11: =COUNTIF(Social_Media_Posts!G:G,A11) -> 3
A12: Card services | B12: =COUNTIF(Social_Media_Posts!G:G,A12) -> 4
A13: Sustainability | B13: =COUNTIF(Social_Media_Posts!G:G,A13) -> 2
A15: Q1 Interpretation
A16: Finding | B16: Digital banking, Fraud & scams, and Financial wellbeing are the most frequent topics in the dataset.
A17: Insight | B17: The high frequency of these topics suggests that customers are particularly concerned with digital banking experiences, financial security, and managing their financial wellbeing. The presence of Fraud & scams alongside Digital banking also indicates that security and fraud prevention are important areas of customer discussion within the dataset.
A18: Q2 Interpretation | B18: Which posts generate the most total engagement? Do the highest-view posts also receive the highest engagement?
A19: Finding | B19: The posts with the highest engagement are generally also among the posts with the highest views. However, the rankings are not identical.
A20: Insight | B20: High reach can contribute to engagement, but views alone do not determine how strongly audiences interact with a post. For example, SM028 received fewer views than SM022 but generated higher total engagement, suggesting that content relevance can influence engagement beyond reach.
